Workbook

Sheet 2026
D2: VOLÚMENES ALMACENADOS EN LOS EMBALSES DE GRAN CANARIA GESTIONADOS POR EL CONSEJO INSULAR DE AGUAS
D4: AÑO 2026
B7: PRESAS | C7: DATOS | D7: NIVEL MÁXIMO | E7: NIVELES EMBALSADOS A FIN DE MES
E8: ENERO | F8: FEBRERO | G8: MARZO | H8: ABRIL | I8: MAYO | J8: JUNIO | K8: JULIO | L8: AGOSTO | M8: SEPTIEMBRE | N8: OCTUBRE | O8: NOVIEMBRE | P8: DICIEMBRE
B9: CHIRA | C9: ALTURA (m) | D9: 32 | E9: 11.8 | F9: 11.82 | G9: 24.65 | H9: 24.32 | I9: 24.3 | J9: 24.01 | K9: 23.63 | L9: 22.93
C10: Volumen (m3) | D10: 5640766 | E10: 460352 | F10: 462404 | G10: 2971555 | H10: 2932913 | I10: 2868151 | J10: 2783991 | K10: 2675780 | L10: 2482504
C11: Variación Respecto mes anterior | E11: =E10-'2025'!P10 -> 152015 | F11: =F10-E10 -> 2052 | G11: =G10-F10 -> 2509151 | H11: =IF(H10=0," ",H10-G10) -> -38642 | I11: =IF(I10=0," ",I10-H10) -> -64762 | J11: =IF(J10=0," ",J10-I10) -> -84160 | K11: =IF(K10=0," ",K10-J10) -> -108211 | L11: =IF(L10=0," ",L10-K10) -> -193276 | M11: =IF(M10=0," ",M10-L10) | N11: =IF(N10=0," ",N10-M10) | O11: =IF(O10=0," ",O10-N10) | P11: =IF(P10=0," ",P10-O10)
C12: %Embalsado respecto a Vmáx | E12: =E10/$D$10 -> 0.081611611 | F12: =F10/$D$10 -> 0.081975391 | G12: =G10/$D$10 -> 0.52679991 | H12: =H10/$D$10 -> 0.51994942 | I12: =I10/$D$10 -> 0.50846835 | J12: =J10/$D$10 -> 0.49354839 | K12: =K10/$D$10 -> 0.47436465 | L12: =L10/$D$10 -> 0.44010051 | ... P12: =P10/$D$10 -> 0
B13: AYAGAURES | C13: ALTURA (m) | D13: 40 | E13: 9.25 | F13: 9.32 | G13: 40 | H13: 38.67 | I13: 37.65 | J13: 36.65 | K13: 35.35 | L13: 34.1
C14: Volumen (m3) | D14: 1849055 | E14: 6497 | F14: 6837 | G14: 1849055 | H14: 1687719 | I14: 1568551 | J14: 1456887 | K14: 1317979 | L14: 1190782
C15: Variación Respecto mes anterior | E15: =E14-'2025'!P14 -> 0 | F15: =IF(F14=0," ", F14-E14) -> 340 | G15: =IF(G14=0," ",G14-F14) -> 1842218 | H15: =IF(H14=0," ", H14-G14) -> -161336 | I15: =IF(I14=0," ", I14-H14) -> -119168 | J15: =IF(J14=0," ", J14-I14) -> -111664 | K15: =IF(K14=0," ", K14-J14) -> -138908 | L15: =IF(L14=0," ", L14-K14) -> -127197 | M15: =IF(M14=0," ", M14-L14) | N15: =IF(N14=0," ", N14-M14) | O15: =IF(O14=0," ", O14-N14) | P15: =IF(P14=0," ", P14-O14)
C16: %Embalsado respecto a Vmáx | E16: =E14/$D$14 -> 0.0035136867 | F16: =F14/$D$14 -> 0.0036975644 | G16: =G14/$D$14 -> 1 | H16: =H14/$D$14 -> 0.91274678 | I16: =I14/$D$14 -> 0.84829873 | J16: =J14/$D$14 -> 0.78790896 | K16: =K14/$D$14 -> 0.71278518 | L16: =L14/$D$14 -> 0.64399491 | ... P16: =P14/$D$14 -> 0
B17: GAMBUESA | C17: ALTURA (m) | D17: 42 | E17: 30.81 | F17: 30.57 | G17: 42 | H17: 42 | I17: 42 | J17: 41.9 | K17: 41.75 | L17: 41.7
C18: Volumen (m3) | D18: 1348707 | E18: 590141 | F18: 577415 | G18: 1348707 | H18: 1348707 | I18: 1348707 | J18: 1340842 | K18: 1329081 | L18: 1324388
C19: Variación Respecto mes anterior | E19: =E18-'2025'!P14 -> 583644 | F19: =IF(F18=0," ",F18-E18) -> -12726 | G19: =IF(G18=0," ",G18-F18) -> 771292 | H19: =IF(H18=0," ",H18-G18) -> 0 | I19: =IF(I18=0," ",I18-H18) -> 0 | J19: =IF(J18=0," ",J18-I18) -> -7865 | K19: =IF(K18=0," ",K18-J18) -> -11761 | L19: =IF(L18=0," ",L18-K18) -> -4693 | M19: =IF(M18=0," ",M18-L18) | ... P19: =IF(P18=0," ",P18-O18)
C20: %Embalsado respecto a Vmáx | E20: =E18/$D$18 -> 0.43756057 | F20: =F18/$D$18 -> 0.42812486 | G20: =G18/$D$18 -> 1 | H20: =H18/$D$18 -> 1 | I20: =I18/$D$18 -> 1 | J20: =J18/$D$18 -> 0.99416849 | K20: =K18/$D$18 -> 0.98544828 | L20: =L18/$D$18 -> 0.98196866 | ... P20: =P18/$D$18 -> 0
B21: EL MULATO | C21: ALTURA (m) | D21: 35 | E21: 25,32 | F21: 25.06 | G21: 35 | H21: 34.7 | I21: 34.48 | J21: 34.3 | K21: 34.09 | L21: 33.8
C22: Volumen (m3) | D22: 759685 | E22: 242207 | F22: 233031 | G22: 759685 | H22: 737847 | I22: 722095 | J22: 709375 | K22: 694731 | L22: 674850
C23: Variación Respecto mes anterior | E23: =E22-'2025'!P22 -> 59839 | F23: =IF(F22=0," ",F22-E22) -> -9176 | G23: =IF(G22=0," ",G22-F22) -> 526654 | H23: =IF(H22=0," ",H22-G22) -> -21838 | I23: =IF(I22=0," ",I22-H22) -> -15752 | J23: =IF(J22=0," ",J22-I22) -> -12720 | K23: =IF(K22=0," ",K22-J22) -> -14644 | L23: =IF(L22=0," ",L22-K22) -> -19881 | M23: =IF(M22=0," ",M22-L22) | ... P23: =IF(P22=0," ",P22-O22)
C24: %Embalsado respecto a Vmáx | E24: =E22/$D$22 -> 0.31882557 | F24: =F22/$D$22 -> 0.30674688 | G24: =G22/$D$22 -> 1 | H24: =H22/$D$22 -> 0.97125387 | I24: =I22/$D$22 -> 0.95051897 | J24: =J22/$D$22 -> 0.93377518 | K24: =K22/$D$22 -> 0.91449877 | L24: =L22/$D$22 -> 0.88832872 | ... P24: =P22/$D$22 -> 0
B25: CANDELARIA | C25: ALTURA (m) | D25: 25 | E25: 25 | F25: 23.35 | G25: 25 | H25: 23.25 | I25: 22.1 | J25: 20.8 | K25: 20.1 | L25: 19.05
C26: Volumen (m3) | D26: 396884 | E26: 396884 | F26: 323081 | G26: 396884 | H26: 318896 | I26: 273089 | J26: 226048 | K26: 202757 | L26: 170736
C27: Variación Respecto mes anterior | E27: =E26-'2025'!P26 -> 238718 | F27: =IF(F26=0," ",F26-E26) -> -73803 | G27: =IF(G26=0," ",G26-F26) -> 73803 | H27: =IF(H26=0," ",H26-G26) -> -77988 | I27: =IF(I26=0," ",I26-H26) -> -45807 | J27: =IF(J26=0," ",J26-I26) -> -47041 | K27: =IF(K26=0," ",K26-J26) -> -23291 | L27: =IF(L26=0," ",L26-K26) -> -32021 | M27: =IF(M26=0," ",M26-L26) | ... P27: =IF(P26=0," ",P26-O26)
C28: %Embalsado respecto a Vmáx | E28: =E26/$D$26 -> 1 | F28: =F26/$D$26 -> 0.8140439 | G28: =G26/$D$26 -> 1 | H28: =H26/$D$26 -> 0.80349926 | I28: =I26/$D$26 -> 0.68808266 | J28: =J26/$D$26 -> 0.56955685 | K28: =K26/$D$26 -> 0.51087219 | L28: =L26/$D$26 -> 0.43019119 | ... P28: =P26/$D$26 -> 0
B29: FATAGA | C29: ALTURA (m) | D29: 32 | E29: 10.65 | F29: 10.48 | G29: 32 | H29: 32 | I29: 30 | J29: 29.27 | K29: 28.6 | L29: 27.3
C30: Volumen (m3) | D30: 327894 | E30: 13241 | F30: 12888 | G30: 327894 | H30: 327894 | I30: 275031 | J30: 256922 | K30: 240864 | L30: 211332
C31: Variación Respecto mes anterior | E31: =E30-'2025'!P30 -> 5185 | F31: =IF(F30=0," ",F30-E30) -> -353 | G31: =IF(G30=0," ",G30-F30) -> 315006 | H31: =IF(H30=0," ",H30-G30) -> 0 | I31: =IF(I30=0," ",I30-H30) -> -52863 | J31: =IF(J30=0," ",J30-I30) -> -18109 | K31: =IF(K30=0," ",K30-J30) -> -16058 | L31: =IF(L30=0," ",L30-K30) -> -29532 | M31: =IF(M30=0," ",M30-L30) | ... P31: =IF(P30=0," ",P30-O30)
C32: %Embalsado respecto a Vmáx | E32: =E30/$D$30 -> 0.040381953 | F32: =F30/$D$30 -> 0.039305385 | G32: =G30/$D$30 -> 1 | H32: =H30/$D$30 -> 1 | I32: =I30/$D$30 -> 0.83878022 | J32: =J30/$D$30 -> 0.783552 | K32: =K30/$D$30 -> 0.73457886 | L32: =L30/$D$30 -> 0.64451317 | ... P32: =P30/$D$30 -> 0
B33: VAQUERO | C33: ALTURA (m) | D33: 35 | E33: 35 | F33: 33.85 | G33: 35 | H33: 34.75 | I33: 34.2 | J33: 33.51 | K33: 33.2 | L33: 32.58
C34: Volumen (m3) | D34: 267041 | E34: 267041 | F34: 242555 | G34: 267041 | H34: 261579 | I34: 249838 | J34: 235599 | K34: 229352 | L34: 217144
C35: Variación Respecto mes anterior | E35: =E34-'2025'!P34 -> 90981 | F35: =IF(F34=0," ",F34-E34) -> -24486 | G35: =IF(G34=0,"0",G34-F34) -> 24486 | H35: =IF(H34=0," ",H34-G34) -> -5462 | I35: =IF(I34=0," ",I34-H34) -> -11741 | J35: =IF(J34=0," ",J34-I34) -> -14239 | K35: =IF(K34=0," ",K34-J34) -> -6247 | L35: =IF(L34=0," ",L34-K34) -> -12208 | M35: =IF(M34=0," ",M34-L34) | N35: =IF(N34=0," ",N34-M34) | O35: =IF(O34=0," ",O34-N34) | P35: =IF(P34=0," ",P34-O34)
C36: %Embalsado respecto a Vmáx | E36: =E34/$D$34 -> 1 | F36: =F34/$D$34 -> 0.90830622 | G36: =G34/$D$34 -> 1 | H36: =H34/$D$34 -> 0.97954621 | I36: =I34/$D$34 -> 0.93557918 | J36: =J34/$D$34 -> 0.88225778 | K36: =K34/$D$34 -> 0.85886437 | L36: =L34/$D$34 -> 0.81314854 | ... P36: =P34/$D$34 -> 0
B37: VOLUMEN TEÓRICO TOTAL | D37: =D10+D14+D18+D22+D26+D30+D34 -> 10590032 | E37: =E10+E14+E18+E22+E26+E30+E34 -> 1976363 | F37: =F10+F14+F18+F22+F26+F30+F34 -> 1858211 | G37: =G10+G14+G18+G22+G26+G30+G34 -> 7920821 | H37: =H10+H14+H18+H22+H26+H30+H34 -> 7615555 | I37: =I10+I14+I18+I22+I26+I30+I34 -> 7305462 | J37: =J10+J14+J18+J22+J26+J30+J34 -> 7009664 | K37: =K10+K14+K18+K22+K26+K30+K34 -> 6690544 | ... P37: =P10+P14+P18+P22+P26+P30+P34 -> 0
B38: VARIACIÓN TOTAL RESPECTO MES ANTERIOR | E38: =E37-'2025'!P37 -> 708139 | F38: =IF(F37=0," ",F37-E37) -> -118152 | G38: =IF(G37=0," ",G37-F37) -> 6062610 | H38: =IF(H37=0," ",H37-G37) -> -305266 | I38: =IF(I37=0," ",I37-H37) -> -310093 | J38: =IF(J37=0," ",J37-I37) -> -295798 | K38: =IF(K37=0," ",K37-J37) -> -319120 | L38: =IF(L37=0," ",L37-K37) -> -418808 | M38: =IF(M37=0," ",M37-L37) | ... P38: =IF(P37=0," ",P37-O37)
B39: %EMBALSADO TOTAL RESPECTO A Vmáx. | E39: =E37/$D$37 -> 0.18662484 | F39: =F37/$D$37 -> 0.17546793 | G39: =G37/$D$37 -> 0.74795062 | H39: =H37/$D$37 -> 0.71912483 | I39: =I37/$D$37 -> 0.68984324 | J39: =J37/$D$37 -> 0.6619115 | K39: =K37/$D$37 -> 0.63177751 | L39: =L37/$D$37 -> 0.59223013 | ... P39: =P37/$D$37 -> 0
B41: COMUNIDAD DE AGUAS LA LUMBRE (participa en un 91,75% por el Cabildo) | E41: ENERO | F41: FEBRERO | G41: MARZO | H41: ABRIL | I41: MAYO | J41: JUNIO | K41: JULIO | L41: AGOSTO | M41: SEPTIEMBRE | N41: OCTUBRE | O41: NOVIEMBRE | P41: DICIEMBRE
B42: SORIA | C42: ALTURA (m) | D42: 120 | E42: 0
C43: Volumen (m3) | D43: 13014589 | E43: 0 | F43: 0 | G43: 0 | H43: 0 | I43: 0 | J43: 0 | K43: 0 | L43: 0 | M43: 0 | N43: 0 | O43: 0 | P43: 0
C44: Variación Respecto mes anterior | E44: 0 | F44: 0 | G44: 0 | H44: 0 | I44: 0 | J44: 0 | K44: 0 | L44: 0 | M44: 0 | N44: 0 | O44: 0 | P44: 0
C45: %Embalsado respecto a Vmáx | E45: 0% | F45: 0% | G45: 0% | H45: 0% | I45: 0% | J45: 0% | K45: 0% | L45: 0% | M45: 0% | N45: 0% | O45: 0% | P45: 0%
...

Sheet 2025
D2: VOLÚMENES ALMACENADOS EN LOS EMBALSES DE GRAN CANARIA GESTIONADOS POR EL CONSEJO INSULAR DE AGUAS
D4: AÑO 2025
B7: PRESAS | C7: DATOS | D7: NIVEL MÁXIMO | E7: NIVELES EMBALSADOS A FIN DE MES
E8: ENERO | F8: FEBRERO | G8: MARZO | H8: ABRIL | I8: MAYO | J8: JUNIO | K8: JULIO | L8: AGOSTO | M8: SEPTIEMBRE | N8: OCTUBRE | O8: NOVIEMBRE | P8: DICIEMBRE
B9: CHIRA | C9: ALTURA (m) | D9: 32 | E9: 6.05 | F9: 6.05 | G9: 6.05 | H9: 6.3 | I9: 6.3 | J9: 6.07 | K9: 5.8 | L9: 5.51 | M9: 5.32 | N9: 5.2 | O9: 6.65 | P9: 10.15
C10: Volumen (m3) | D10: 5640766 | E10: 79219 | F10: 79219 | G10: 79219 | H10: 87967 | I10: 87967 | J10: 79898 | K10: 71027 | L10: 62195 | M10: 56784 | N10: 53515 | O10: 101164 | P10: 308337
C11: Variación Respecto mes anterior | E11: =E10-'2024'!P11 -> -1705 | F11: =IF(F10=0," ",F9-E9) -> 0 | G11: =IF(G10=0," ",G9-F9) -> 0 | H11: =IF(H10=0," ",H9-G9) -> 0.25 | I11: =IF(I10=0," ",I9-H9) -> 0 | J11: =J10-I10 -> -8069 | K11: =K10-J10 -> -8871 | L11: =L10-K10 -> -8832 | M11: =M10-L10 -> -5411 | N11: =N10-M10 -> -3269 | O11: =O10-N10 -> 47649 | P11: =P10-O10 -> 207173
C12: %Embalsado respecto a Vmáx | E12: =E10/$D$10 -> 0.014044015 | F12: =F10/$D$10 -> 0.014044015 | G12: =G10/$D$10 -> 0.014044015 | H12: =H10/$D$10 -> 0.015594868 | I12: =I10/$D$10 -> 0.015594868 | J12: =J10/$D$10 -> 0.014164388 | K12: =K10/$D$10 -> 0.01259173 | L12: =L10/$D$10 -> 0.011025985 | ... P12: =P10/$D$10 -> 0.054662257
B13: AYAGAURES | C13: ALTURA (m) | D13: 40 | E13: 10.25 | F13: 9.98 | G13: 9.91 | H13: 9.88 | I13: 9.82 | J13: 9.78 | K13: 9.68 | L13: 9.32 | M13: 9.24 | N13: 9.05 | O13: 9.05 | P13: 9.25
C14: Volumen (m3) | D14: 1849055 | E14: 12371 | F14: 10507 | G14: 10129 | H14: 9944 | I14: 9578 | J14: 9339 | K14: 8756 | L14: 6837 | M14: 6449 | N14: 5541 | O14: 5541 | P14: 6497
C15: Variación Respecto mes anterior | E15: =E14-'2024'!P15 -> -7130 | F15: =IF(F14=0," ", F14-E14) -> -1864 | G15: =IF(G14=0," ",G14-F14) -> -378 | H15: =IF(H14=0," ", H14-G14) -> -185 | I15: =IF(I14=0," ", I14-H14) -> -366 | J15: =IF(J14=0," ", J14-I14) -> -239 | K15: =IF(K14=0," ", K14-J14) -> -583 | L15: =IF(L14=0," ", L14-K14) -> -1919 | M15: =IF(M14=0," ", M14-L14) -> -388 | N15: =IF(N14=0," ", N14-M14) -> -908 | O15: =IF(O14=0," ", O14-N14) -> 0 | P15: =IF(P14=0," ", P14-O14) -> 956
C16: %Embalsado respecto a Vmáx | E16: =E14/$D$14 -> 0.0066904446 | F16: =F14/$D$14 -> 0.0056823621 | G16: =G14/$D$14 -> 0.0054779333 | H16: =H14/$D$14 -> 0.0053778822 | I16: =I14/$D$14 -> 0.0051799433 | J16: =J14/$D$14 -> 0.0050506881 | K16: =K14/$D$14 -> 0.0047353919 | L16: =L14/$D$14 -> 0.0036975644 | ... P16: =P14/$D$14 -> 0.0035136867
B17: GAMBUESA | C17: ALTURA (m) | D17: 42 | E17: 27.89 | F17: 27.35 | G17: 26.85 | H17: 26.83 | I17: 26.2 | J17: 25.75 | K17: 25.13 | L17: 24.14 | M17: 23.33 | N17: 22.62 | O17: 23.55 | P17: 27.45
C18: Volumen (m3) | D18: 1348707 | E18: 447579 | F18: 423993 | G18: 402786 | H18: 402368 | I18: 376596 | J18: 358824 | K18: 335140 | L18: 298793 | M18: 271252 | N18: 247632 | O18: 278359 | P18: 428740
C19: Variación Respecto mes anterior | E19: =E18-'2024'!P19 -> -14320 | F19: =IF(F18=0," ",F18-E18) -> -23586 | G19: =IF(G18=0," ",G18-F18) -> -21207 | H19: =IF(H18=0," ",H18-G18) -> -418 | I19: =IF(I18=0," ",I18-H18) -> -25772 | J19: =IF(J18=0," ",J18-I18) -> -17772 | K19: =IF(K18=0," ",K18-J18) -> -23684 | L19: =IF(L18=0," ",L18-K18) -> -36347 | M19: =IF(M18=0," ",M18-L18) -> -27541 | ... P19: =IF(P18=0," ",P18-O18) -> 150381
C20: %Embalsado respecto a Vmáx | E20: =E18/$D$18 -> 0.33185785 | F20: =F18/$D$18 -> 0.31436999 | G20: =G18/$D$18 -> 0.29864604 | H20: =H18/$D$18 -> 0.29833611 | I20: =I18/$D$18 -> 0.27922744 | J20: =J18/$D$18 -> 0.26605037 | K20: =K18/$D$18 -> 0.24848985 | L20: =L18/$D$18 -> 0.22154033 | ... P20: =P18/$D$18 -> 0.31788965
B21: EL MULATO | C21: ALTURA (m) | D21: 35 | E21: ֊ | F21: 20.88 | G21: 20.88 | H21: 22.1 | I21: 21.87 | J21: 21.62 | K21: 21.3 | L21: 20.85 | M21: 20.52 | N21: 20.28 | O21: 20.97 | P21: 23.5
C22: Volumen (m3) | D22: 759685 | F22: 115090 | G22: 115090 | H22: 143639 | I22: 137634 | J22: 131575 | K22: 124350 | L22: 114452 | M22: 107627 | N22: 102886 | O22: 117023 | P22: 182368
C23: Variación Respecto mes anterior | F23: =IF(F22=0," ",F22-E22) -> 115090 | G23: =IF(G22=0," ",G22-F22) -> 0 | H23: =IF(H22=0," ",H22-G22) -> 28549 | I23: =IF(I22=0," ",I22-H22) -> -6005 | J23: =IF(J22=0," ",J22-I22) -> -6059 | K23: =IF(K22=0," ",K22-J22) -> -7225 | L23: =IF(L22=0," ",L22-K22) -> -9898 | M23: =IF(M22=0," ",M22-L22) -> -6825 | ... P23: =IF(P22=0," ",P22-O22) -> 65345
C24: %Embalsado respecto a Vmáx | E24: ֊ | F24: =F22/$D$22 -> 0.151497 | G24: =G22/$D$22 -> 0.151497 | H24: =H22/$D$22 -> 0.18907705 | I24: =I22/$D$22 -> 0.18117246 | J24: =J22/$D$22 -> 0.17319679 | K24: =K22/$D$22 -> 0.16368626 | L24: =L22/$D$22 -> 0.15065718 | M24: =M22/$D$22 -> 0.14167319 | ... P24: =P22/$D$22 -> 0.24005739
B25: CANDELARIA | C25: ALTURA (m) | D25: 25 | E25: 7.4 | F25: 7.3 | G25: 6.95 | H25: 6.65 | I25: 6.3 | J25: 5.48 | K25: 5.1 | L25: 4.6 | M25: 4.5 | N25: 4.25 | O25: 4.2 | P25: 18.6
C26: Volumen (m3) | D26: 396884 | E26: 12313 | F26: 11922 | G26: 10436 | H26: 9288 | I26: 8073 | J26: 5498 | K26: 4492 | L26: 3352 | M26: 3149 | N26: 2674 | O26: 2568 | P26: 158166
C27: Variación Respecto mes anterior | E27: =E26-'2024'!P27 -> -717 | F27: =IF(F26=0," ",F26-E26) -> -391 | G27: =IF(G26=0," ",G26-F26) -> -1486 | H27: =IF(H26=0," ",H26-G26) -> -1148 | I27: =IF(I26=0," ",I26-H26) -> -1215 | J27: =IF(J26=0," ",J26-I26) -> -2575 | K27: =IF(K26=0," ",K26-J26) -> -1006 | L27: =IF(L26=0," ",L26-K26) -> -1140 | M27: =IF(M26=0," ",M26-L26) -> -203 | ... P27: =IF(P26=0," ",P26-O26) -> 155598
C28: %Embalsado respecto a Vmáx | E28: =E26/$D$26 -> 0.031024178 | F28: =F26/$D$26 -> 0.030039004 | G28: =G26/$D$26 -> 0.026294837 | H28: =H26/$D$26 -> 0.023402304 | I28: =I26/$D$26 -> 0.020340956 | J28: =J26/$D$26 -> 0.013852914 | K28: =K26/$D$26 -> 0.011318169 | L28: =L26/$D$26 -> 0.0084457927 | ... P28: =P26/$D$26 -> 0.39851947
B29: FATAGA | C29: ALTURA (m) | D29: 32 | E29: 5.55 | F29: 5.55 | G29: 5.55 | H29: 7.42 | I29: 7.85 | J29: 7.91 | K29: 5.77 | L29: 5.73 | M29: 5.71 | N29: 5.71 | O29: 5.71 | P29: 8.9
C30: Volumen (m3) | D30: 327894 | E30: 624 | F30: 624 | G30: 624 | H30: 4210 | I30: 5260 | J30: 5412 | K30: 934 | L30: 875 | M30: 846 | N30: 846 | O30: 846 | P30: 8056
C31: Variación Respecto mes anterior | E31: =E30-'2024'!P31 -> 0 | F31: =IF(F30=0," ",F30-E30) -> 0 | G31: =IF(G30=0," ",G30-F30) -> 0 | H31: =IF(H30=0," ",H30-G30) -> 3586 | I31: =IF(I30=0," ",I30-H30) -> 1050 | J31: =IF(J30=0," ",J30-I30) -> 152 | K31: =IF(K30=0," ",K30-J30) -> -4478 | L31: =IF(L30=0," ",L30-K30) -> -59 | M31: =IF(M30=0," ",M30-L30) -> -29 | ... P31: =IF(P30=0," ",P30-O30) -> 7210
C32: %Embalsado respecto a Vmáx | E32: =E30/$D$30 -> 0.001903054 | F32: =F30/$D$30 -> 0.001903054 | G32: =G30/$D$30 -> 0.001903054 | H32: =H30/$D$30 -> 0.012839515 | I32: =I30/$D$30 -> 0.01604177 | J32: =J30/$D$30 -> 0.016505334 | K32: =K30/$D$30 -> 0.0028484815 | L32: =L30/$D$30 -> 0.0026685453 | ... P32: =P30/$D$30 -> 0.024568916
B33: VAQUERO | C33: ALTURA (m) | D33: 35 | E33: 0 | F33: 0 | G33: 0 | H33: 0 | I33: 0 | J33: 0 | K33: 0 | L33: 0 | M33: 0 | N33: 0 | O33: 5.45 | P33: 30.3
C34: Volumen (m3) | D34: 267041 | E34: 0 | F34: 1e-06 | G34: 0 | H34: 0 | I34: 0 | J34: 0 | K34: 0 | L34: 0 | M34: 0 | N34: 0 | O34: 1049 | P34: 176060
C35: Variación Respecto mes anterior | E35: =E34-'2024'!P35 -> -61 | F35: =IF(F34=0," ",F34-E34) -> 1e-06 | G35: =IF(G34=0,"0",G34-F34) -> 0 | H35: =IF(H34=0,"0",H34-G34) -> 0 | I35: 0 | J35: 0 | K35: 0 | L35: 0 | M35: 0 | N35: 0 | O35: =IF(O34=0," ",O34-N34) -> 1049 | P35: =IF(P34=0," ",P34-O34) -> 175011
C36: %Embalsado respecto a Vmáx | E36: =E34/$D$34 -> 0 | F36: =F34/$D$34 -> 3.7447433e-12 | G36: =G34/$D$34 -> 0 | H36: =H34/$D$34 -> 0 | I36: =I34/$D$34 -> 0 | J36: =J34/$D$34 -> 0 | K36: =K34/$D$34 -> 0 | L36: =L34/$D$34 -> 0 | ... P36: =P34/$D$34 -> 0.65929951
B37: VOLUMEN TEÓRICO TOTAL | D37: =D10+D14+D18+D22+D26+D30+D34 -> 10590032 | E37: =E10+E14+E18+E22+E26+E30+E34+133975 -> 686081 | F37: =F10+F14+F18+F22+F26+F30+F34 -> 641355 | G37: =G10+G14+G18+G22+G26+G30+G34 -> 618284 | H37: =H10+H14+H18+H22+H26+H30+H34 -> 657416 | I37: =I10+I14+I18+I22+I26+I30+I34 -> 625108 | J37: =J10+J14+J18+J22+J26+J30+J34 -> 590546 | K37: =K10+K14+K18+K22+K26+K30+K34 -> 544699 | L37: =L10+L14+L18+L22+L26+L30+L34 -> 486504 | M37: =M10+M14+M18+M22+M26+M30+M34 -> 446107 | ... P37: =P10+P14+P18+P22+P26+P30+P34 -> 1268224
B38: VARIACIÓN TOTAL RESPECTO MES ANTERIOR | E38: -66658 | F38: =IF(F37=0," ",F37-E37) -> -44726 | G38: =IF(G37=0," ",G37-F37) -> -23071 | H38: =IF(H37=0," ",H37-G37) -> 39132 | I38: =IF(I37=0," ",I37-H37) -> -32308 | J38: =IF(J37=0," ",J37-I37) -> -34562 | K38: =IF(K37=0," ",K37-J37) -> -45847 | L38: =IF(L37=0," ",L37-K37) -> -58195 | M38: =IF(M37=0," ",M37-L37) -> -40397 | ... P38: =IF(P37=0," ",P37-O37) -> 761674
B39: %EMBALSADO TOTAL RESPECTO A Vmáx. | E39: =E37/$D$37 -> 0.064785546 | F39: =F37/$D$37 -> 0.06056214 | G39: =G37/$D$37 -> 0.058383582 | H39: =H37/$D$37 -> 0.062078755 | I39: =I37/$D$37 -> 0.059027961 | J39: =J37/$D$37 -> 0.055764326 | K39: =K37/$D$37 -> 0.051435066 | L39: =L37/$D$37 -> 0.045939805 | ... P39: =P37/$D$37 -> 0.11975639
B41: COMUNIDAD DE AGUAS LA LUMBRE (participa en un 91,75% por el Cabildo) | E41: ENERO | F41: FEBRERO | G41: MARZO | H41: ABRIL | I41: MAYO | J41: JUNIO | K41: JULIO | L41: AGOSTO | M41: SEPTIEMBRE | N41: OCTUBRE | O41: NOVIEMBRE | P41: DICIEMBRE
B42: SORIA | C42: ALTURA (m) | D42: 120
C43: Volumen (m3) | D43: 13014589 | E43: 0 | F43: 0 | G43: 0 | H43: 0 | I43: 0 | J43: 0 | K43: 0 | L43: 0 | M43: 0 | N43: 0 | O43: 0 | P43: 0
C44: Variación Respecto mes anterior | E44: 0 | F44: 0 | G44: 0 | H44: 0 | I44: 0 | J44: 0 | K44: 0 | L44: 0 | M44: 0 | N44: 0 | O44: 0 | P44: 0
C45: %Embalsado respecto a Vmáx | E45: 0% | F45: 0% | G45: 0% | H45: 0% | I45: 0% | J45: 0% | K45: 0% | L45: 0% | M45: 0% | N45: 0% | O45: 0% | P45: 0%
...

Sheet 2024
D2: VOLÚMENES ALMACENADOS EN LOS EMBALSES DE GRAN CANARIA GESTIONADOS POR EL CONSEJO INSULAR DE AGUAS
D4: AÑO 2024
B8: PRESAS | C8: DATOS | D8: NIVEL MÁXIMO | E8: NIVELES EMBALSADOS A FIN DE MES
E9: ENERO | F9: FEBRERO | G9: MARZO | H9: ABRIL | I9: MAYO | J9: JUNIO | K9: JULIO | L9: AGOSTO | M9: SEPTIEMBRE | N9: OCTUBRE | O9: NOVIEMBRE | P9: DICIEMBRE
B10: CHIRA | C10: ALTURA (m) | D10: 32 | E10: 9.58 | F10: 9.37 | G10: 9.07 | H10: 8.59 | I10: 8.18 | J10: 7.84 | K10: 7.31 | L10: 6.83 | M10: 6.47 | N10: 6.3 | O10: 6.25 | P10: 6.1
C11: Volumen (m3) | D11: 5640766 | E11: 263333 | F11: 247788 | G11: 226746 | H11: 196075 | I11: 172492 | J11: 154513 | K11: 129053 | L11: 108381 | M11: 94238 | N11: 87697 | O11: 86172 | P11: 80924
C12: Variación Respecto mes anterior | E12: -19269 | F12: =F11-E11 -> -15545 | G12: =G11-F11 -> -21042 | H12: =H11-G11 -> -30671 | I12: =I11-H11 -> -23583 | J12: =J11-I11 -> -17979 | K12: =K11-J11 -> -25460 | L12: =L11-K11 -> -20672 | M12: =M11-L11 -> -14143 | ... P12: =P11-O11 -> -5248
C13: %Embalsado respecto a Vmáx | E13: =E11/$D$11 -> 0.046683908 | F13: =F11/$D$11 -> 0.043928076 | G13: =G11/$D$11 -> 0.040197732 | H13: =H11/$D$11 -> 0.03476035 | I13: =I11/$D$11 -> 0.030579535 | J13: =J11/$D$11 -> 0.027392202 | K13: =K11/$D$11 -> 0.02287863 | L13: =L11/$D$11 -> 0.01921388 | ... P13: =P11/$D$11 -> 0.014346279
B14: AYAGAURES | C14: ALTURA (m) | D14: 40 | E14: 14.72 | F14: 14.63 | G14: 14.59 | H14: 14.55 | I14: 14.48 | J14: 14.36 | K14: 14.19 | L14: 13.98 | M14: 13.05 | N14: 12.65 | O14: 11.85 | P14: 11.15
C15: Volumen (m3) | D15: 1849055 | E15: 71243 | F15: 69365 | G15: 68540 | H15: 67519 | I15: 66104 | J15: 63921 | K15: 60637 | L15: 56551 | M15: 41250 | N15: 35780 | O15: 26306 | P15: 19501
C16: Variación Respecto mes anterior | E16: -1483 | F16: =F15-E15 -> -1878 | G16: =G15-F15 -> -825 | H16: =H15-G15 -> -1021 | I16: =I15-H15 -> -1415 | J16: =J15-I15 -> -2183 | K16: =K15-J15 -> -3284 | L16: =L15-K15 -> -4086 | M16: =M15-L15 -> -15301 | ... P16: =P15-O15 -> -6805
C17: %Embalsado respecto a Vmáx | E17: =E15/$D$15 -> 0.038529411 | F17: =F15/$D$15 -> 0.037513757 | G17: =G15/$D$15 -> 0.037067583 | H17: =H15/$D$15 -> 0.036515409 | I17: =I15/$D$15 -> 0.035750153 | J17: =J15/$D$15 -> 0.03456955 | K17: =K15/$D$15 -> 0.032793508 | L17: =L15/$D$15 -> 0.030583731 | ... P17: =P15/$D$15 -> 0.010546468
B18: GAMBUESA | C18: ALTURA (m) | D18: 42 | E18: 32.95 | F18: 32.47 | G18: 32.29 | H18: 31.85 | I18: 31.31 | J18: 30.92 | K18: 30.25 | L18: 29.57 | M18: 29.05 | N18: 28.6 | O18: 28.4 | P18: 28.2
C19: Volumen (m3) | D19: 1348707 | E19: 712930 | F19: 683987 | G19: 673323 | H19: 647154 | I19: 617306 | J19: 595501 | K19: 560745 | L19: 526452 | M19: 500806 | N19: 479718 | O19: 470986 | P19: 461899
C20: Variación Respecto mes anterior | E20: -29550 | F20: =F19-E19 -> -28943 | G20: =G19-F19 -> -10664 | H20: =H19-G19 -> -26169 | I20: =I19-H19 -> -29848 | J20: =J19-I19 -> -21805 | K20: =K19-J19 -> -34756 | L20: =L19-K19 -> -34293 | M20: =M19-L19 -> -25646 | ... P20: =P19-O19 -> -9087
C21: %Embalsado respecto a Vmáx | E21: =E19/$D$19 -> 0.52860258 | F21: =F19/$D$19 -> 0.50714277 | G21: =G19/$D$19 -> 0.49923593 | H21: =H19/$D$19 -> 0.47983291 | I21: =I19/$D$19 -> 0.45770208 | J21: =J19/$D$19 -> 0.44153474 | K21: =K19/$D$19 -> 0.41576488 | L21: =L19/$D$19 -> 0.3903383 | ... P21: =P19/$D$19 -> 0.34247542
B22: EL MULATO | C22: ALTURA (m) | D22: 35 | E22: 26.94 | F22: 26.82 | G22: 26.71 | H22: 26.51 | I22: 24.83 | J22: 24.48 | K22: 23.98 | L22: 23.26 | M22: 22.74 | N22: 22.23 | O22: 21.82 | P22: 21.71
C23: Volumen (m3) | D23: 759685 | E23: 303742 | F23: 299275 | G23: 294847 | H23: 286499 | I23: 225085 | J23: 213306 | K23: 197141 | L23: 174973 | M23: 160541 | N23: 146967 | O23: 136651 | P23: 133975
C24: Variación Respecto mes anterior | E24: -4916 | F24: =F23-E23 -> -4467 | G24: =G23-F23 -> -4428 | H24: =H23-G23 -> -8348 | I24: =I23-H23 -> -61414 | J24: =J23-I23 -> -11779 | K24: =K23-J23 -> -16165 | L24: =L23-K23 -> -22168 | M24: =M23-L23 -> -14432 | ... P24: =P23-O23 -> -2676
C25: %Embalsado respecto a Vmáx | E25: =E23/$D$23 -> 0.39982624 | F25: =F23/$D$23 -> 0.39394618 | G25: =G23/$D$23 -> 0.38811744 | H25: =H23/$D$23 -> 0.37712868 | I25: =I23/$D$23 -> 0.29628728 | J25: =J23/$D$23 -> 0.28078217 | K25: =K23/$D$23 -> 0.25950361 | L25: =L23/$D$23 -> 0.23032309 | ... P25: =P23/$D$23 -> 0.17635599
B26: CANDELARIA | C26: ALTURA (m) | D26: 25 | E26: 12.85 | F26: 12.5 | G26: 12.1 | H26: 11.8 | I26: 11.2 | J26: 10.7 | K26: 9.9 | L26: 9.2 | M26: 8.6 | N26: 8.2 | O26: 7.85 | P26: 7.55
C27: Volumen (m3) | D27: 396884 | E27: 52153 | F27: 48342 | G27: 44270 | H27: 41400 | I27: 36077 | J27: 32019 | K27: 26214 | L27: 21754 | M27: 18313 | N27: 16192 | O27: 14442 | P27: 13030
C28: Variación Respecto mes anterior | E28: -6484 | F28: =F27-E27 -> -3811 | G28: =G27-F27 -> -4072 | H28: =H27-G27 -> -2870 | I28: =I27-H27 -> -5323 | J28: =J27-I27 -> -4058 | K28: =K27-J27 -> -5805 | L28: =L27-K27 -> -4460 | M28: =M27-L27 -> -3441 | ... P28: =P27-O27 -> -1412
C29: %Embalsado respecto a Vmáx | E29: =E27/$D$27 -> 0.13140615 | F29: =F27/$D$27 -> 0.12180385 | G29: =G27/$D$27 -> 0.11154393 | H29: =H27/$D$27 -> 0.1043126 | I29: =I27/$D$27 -> 0.090900616 | J29: =J27/$D$27 -> 0.080675966 | K29: =K27/$D$27 -> 0.066049526 | L29: =L27/$D$27 -> 0.054811985 | ... P29: =P27/$D$27 -> 0.032830752
B30: FATAGA | C30: ALTURA (m) | D30: 32 | E30: 5.82 | F30: 5.82 | G30: 5.82 | H30: 5.55 | I30: 0 | N30: 5.55 | O30: 5.55 | P30: 5.55
C31: Volumen (m3) | D31: 327894 | E31: 1010 | F31: 1010 | G31: 1010 | H31: 624 | I31: 0 | J31: 0 | K31: 0 | L31: 0 | M31: 0 | N31: 624 | O31: 624 | P31: 624
C32: Variación Respecto mes anterior | E32: 0 | F32: =F31-E31 -> 0 | G32: =G31-F31 -> 0 | H32: =H31-G31 -> -386 | I32: =I31-H31 -> -624 | J32: =J31-I31 -> 0 | K32: =K31-J31 -> 0 | L32: =L31-K31 -> 0 | M32: =M31-L31 -> 0 | ... P32: =P31-O31 -> 0
C33: %Embalsado respecto a Vmáx | E33: =E31/$D$31 -> 0.0030802637 | F33: =F31/$D$31 -> 0.0030802637 | G33: =G31/$D$31 -> 0.0030802637 | H33: =H31/$D$31 -> 0.001903054 | I33: =I31/$D$31 -> 0 | J33: =J31/$D$31 -> 0 | K33: =K31/$D$31 -> 0 | L33: =L31/$D$31 -> 0 | ... P33: =P31/$D$31 -> 0.001903054
B34: VAQUERO | C34: ALTURA (m) | D34: 35 | E34: 18.02 | F34: 16.9 | G34: 16.2 | H34: 14.68 | I34: 12.9 | J34: 10.6 | K34: 7.6 | L34: 5.75 | N34: 3.45 | O34: 3.85 | P34: 3.85
C35: Volumen (m3) | D35: 267041 | E35: 39507 | F35: 33253 | G35: 29807 | H35: 23230 | I35: 16724 | J35: 9859 | K35: 3583 | L35: 1333 | M35: 0 | N35: 0 | O35: 61 | P35: 61
C36: Variación Respecto mes anterior | E36: -4956 | F36: =F35-E35 -> -6254 | G36: =G35-F35 -> -3446 | H36: =H35-G35 -> -6577 | I36: =I35-H35 -> -6506 | J36: =J35-I35 -> -6865 | K36: =K35-J35 -> -6276 | L36: =L35-K35 -> -2250 | M36: =M35-L35 -> -1333 | ... P36: =P35-O35 -> 0
C37: %Embalsado respecto a Vmáx | E37: =E35/$D$35 -> 0.14794357 | F37: =F35/$D$35 -> 0.12452395 | G37: =G35/$D$35 -> 0.11161956 | H37: =H35/$D$35 -> 0.086990387 | I37: =I35/$D$35 -> 0.062627087 | J37: =J35/$D$35 -> 0.036919424 | K37: =K35/$D$35 -> 0.013417415 | L37: =L35/$D$35 -> 0.0049917428 | ... P37: =P35/$D$35 -> 0.00022842934
B38: VOLUMEN TEÓRICO TOTAL | D38: =D11+D15+D19+D23+D27+D31+D35 -> 10590032 | E38: =E11+E15+E19+E23+E27+E31+E35 -> 1443918 | F38: =F11+F15+F19+F23+F27+F31+F35 -> 1383020 | G38: =G11+G15+G19+G23+G27+G31+G35 -> 1338543 | H38: =H11+H15+H19+H23+H27+H31+H35 -> 1262501 | I38: =I11+I15+I19+I23+I27+I31+I35 -> 1133788 | J38: =J11+J15+J19+J23+J27+J31+J35 -> 1069119 | K38: =K11+K15+K19+K23+K27+K31+K35 -> 977373 | ... P38: =P11+P15+P19+P23+P27+P31+P35 -> 710014
B39: VARIACIÓN TOTAL RESPECTO MES ANTERIOR | E39: -66658 | F39: =F38-E38 -> -60898 | G39: =G38-F38 -> -44477 | H39: =H38-G38 -> -76042 | I39: =I38-H38 -> -128713 | J39: =J38-I38 -> -64669 | K39: =K38-J38 -> -91746 | L39: =L38-K38 -> -87929 | M39: =M38-L38 -> -74296 | ... P39: =P38-O38 -> -25228
B40: %EMBALSADO TOTAL RESPECTO A Vmáx. | E40: =E38/$D$38 -> 0.1363469 | F40: =F38/$D$38 -> 0.13059639 | G40: =G38/$D$38 -> 0.1263965 | H40: =H38/$D$38 -> 0.11921598 | I40: =I38/$D$38 -> 0.10706181 | J40: =J38/$D$38 -> 0.10095522 | K40: =K38/$D$38 -> 0.092291789 | L40: =L38/$D$38 -> 0.083988792 | ... P40: =P38/$D$38 -> 0.067045501
B42: COMUNIDAD DE AGUAS LA LUMBRE (participa en un 91,75% por el Cabildo) | E42: Columna4 | F42: Columna5 | G42: Columna6 | H42: Columna7 | I42: Columna8 | J42: Columna9 | K42: Columna10 | L42: Columna11 | M42: Columna12 | N42: Columna13 | O42: Columna14 | P42: Columna15
B43: SORIA | C43: ALTURA (m) | D43: 120
C44: Volumen (m3) | D44: 13014589 | E44: 0 | F44: 0 | G44: 0 | H44: 0 | I44: 0 | J44: 0 | K44: 0 | L44: 0 | M44: 0 | N44: 0 | O44: 0 | P44: 0
C45: Variación Respecto mes anterior | E45: 0 | F45: 0 | G45: 0 | H45: 0 | I45: 0 | J45: 0 | K45: 0 | L45: 0 | M45: 0 | N45: 0 | O45: 0 | P45: 0
C46: %Embalsado respecto a Vmáx | E46: 0% | F46: 0% | G46: 0% | H46: 0% | I46: 0% | J46: 0% | K46: 0% | L46: 0% | M46: 0% | N46: 0% | O46: 0% | P46: 0%
...
